<?xml version="1.0" encoding="utf-8"?>
<!-- =================================================================================== -->
<!-- |    This document was autogenerated by xacro from ic120.xacro                    | -->
<!-- |    EDITING THIS FILE BY HAND IS NOT RECOMMENDED                                 | -->
<!-- =================================================================================== -->
<robot name="ic120">
  <!-- <xacro:property name="model_offset_x" value="-1.5" />
  <xacro:property name="model_offset_y" value="-3.1" /> -->
  <link name="base_link"/>
  <link name="track_frame_link">
    <visual>
      <geometry>
        <mesh filename="package://ic120_model/mesh/track_frame.stl"/>
      </geometry>
      <origin rpy="0 0 1.57079632675" xyz="3.1 -1.5 0"/>
      <material name="Gray">
        <color rgba="0.7 0.7 0.7 1.0"/>
      </material>
    </visual>
    <inertial>
      <mass value="1"/>
      <inertia ixx="1" ixy="0.0" ixz="0.0" iyy="1" iyz="0.0" izz="1"/>
    </inertial>
  </link>
  <joint name="track_frame_joint" type="fixed">
    <origin rpy="0 0 0" xyz="0 0 0"/>
    <parent link="base_link"/>
    <child link="track_frame_link"/>
    <axis xyz="0 0 1"/>
  </joint>
  <link name="track_belt_link">
    <visual>
      <geometry>
        <mesh filename="package://ic120_model/mesh/track_belt.stl"/>
      </geometry>
      <origin rpy="0 0 1.57079632675" xyz="3.1 -1.5 0"/>
      <material name="Black">
        <color rgba="0 0 0 1.0"/>
      </material>
    </visual>
    <inertial>
      <mass value="1"/>
      <inertia ixx="1" ixy="0.0" ixz="0.0" iyy="1" iyz="0.0" izz="1"/>
    </inertial>
  </link>
  <joint name="track_belt_joint" type="fixed">
    <origin rpy="0 0 0" xyz="0 0 0"/>
    <parent link="track_frame_link"/>
    <child link="track_belt_link"/>
    <axis xyz="0 0 1"/>
  </joint>
  <link name="upper_frame_link">
    <visual>
      <geometry>
        <mesh filename="package://ic120_model/mesh/upper.stl"/>
      </geometry>
      <origin rpy="0 0 1.57079632675" xyz="3.1 -1.5 0"/>
      <material name="Black">
        <color rgba="0 0 0 1.0"/>
      </material>
    </visual>
    <visual>
      <geometry>
        <mesh filename="package://ic120_model/mesh/cabin.stl"/>
      </geometry>
      <origin rpy="0 0 1.57079632675" xyz="3.1 -1.5 0"/>
      <material name="Black">
        <color rgba="0 0 0 1.0"/>
      </material>
    </visual>
    <visual>
      <geometry>
        <mesh filename="package://ic120_model/mesh/cabin_window.stl"/>
      </geometry>
      <origin rpy="0 0 1.57079632675" xyz="3.1 -1.5 0"/>
      <material name="Gray">
        <color rgba="0.7 0.7 0.7 0.2"/>
      </material>
    </visual>
    <visual>
      <geometry>
        <mesh filename="package://ic120_model/mesh/engine.stl"/>
      </geometry>
      <origin rpy="0 0 1.57079632675" xyz="3.1 -1.5 0"/>
      <material name="Teal">
        <color rgba="0 0.5 0.5 1.0"/>
      </material>
    </visual>
    <inertial>
      <mass value="1"/>
      <inertia ixx="1" ixy="0.0" ixz="0.0" iyy="1" iyz="0.0" izz="1"/>
    </inertial>
  </link>
  <joint name="upper_frame_joint" type="fixed">
    <origin rpy="0 0 0" xyz="0 0 0"/>
    <parent link="track_frame_link"/>
    <child link="upper_frame_link"/>
    <axis xyz="0 0 1"/>
  </joint>
  <link name="container_link">
    <visual>
      <geometry>
        <mesh filename="package://ic120_model/mesh/container.stl"/>
      </geometry>
      <origin rpy="0 1.57079632675 1.57079632675" xyz="5.4068 -1.5619 1.5034"/>
      <material name="Teal">
        <color rgba="0 0.5 0.5 1.0"/>
      </material>
    </visual>
    <inertial>
      <mass value="1"/>
      <inertia ixx="1" ixy="0.0" ixz="0.0" iyy="1" iyz="0.0" izz="1"/>
    </inertial>
  </link>
  <joint name="container_joint" type="revolute">
    <origin rpy="1.57079632675 0 0" xyz="-2.3068 0.0034 1.5619"/>
    <parent link="upper_frame_link"/>
    <child link="container_link"/>
    <axis xyz="0 0 1"/>
    <limit effort="100000" lower="-3.14" upper="3.14" velocity="100"/>
  </joint>
  <link name="back_door_link">
    <visual>
      <geometry>
        <mesh filename="package://ic120_model/mesh/back_door.stl"/>
      </geometry>
      <origin rpy="0 1.57079632675 1.57079632675" xyz="5.4766 -2.3816 1.5034"/>
      <material name="Teal">
        <color rgba="0 0.5 0.5 1.0"/>
      </material>
    </visual>
    <inertial>
      <mass value="1"/>
      <inertia ixx="1" ixy="0.0" ixz="0.0" iyy="1" iyz="0.0" izz="1"/>
    </inertial>
  </link>
  <joint name="back_door_joint" type="revolute">
    <origin rpy="0 0 0" xyz="-0.0698 0.8197 0"/>
    <parent link="container_link"/>
    <child link="back_door_link"/>
    <axis xyz="0 0 1"/>
    <limit effort="100000" lower="-3.14" upper="3.14" velocity="100"/>
  </joint>
  <link name="cylinder_L_link">
    <visual>
      <geometry>
        <mesh filename="package://ic120_model/mesh/cylinder_L.stl"/>
      </geometry>
      <origin rpy="0 1.57079632675 1.57079632675" xyz="5.0549 -1.3634 2.3016"/>
      <material name="Black">
        <color rgba="0 0 0 1.0"/>
      </material>
    </visual>
    <inertial>
      <mass value="1"/>
      <inertia ixx="1" ixy="0.0" ixz="0.0" iyy="1" iyz="0.0" izz="1"/>
    </inertial>
  </link>
  <joint name="cylinder_L_joint" type="revolute">
    <origin rpy="1.57079632675 0 0" xyz="-1.9549 0.8016 1.3634"/>
    <parent link="upper_frame_link"/>
    <child link="cylinder_L_link"/>
    <axis xyz="0 0 1"/>
    <limit effort="100000" lower="-3.14" upper="3.14" velocity="100"/>
  </joint>
  <link name="cylinder_R_link">
    <visual>
      <geometry>
        <mesh filename="package://ic120_model/mesh/cylinder_R.stl"/>
      </geometry>
      <origin rpy="0 1.57079632675 1.57079632675" xyz="5.0549 -1.3634 0.7006"/>
      <material name="Black">
        <color rgba="0 0 0 1.0"/>
      </material>
    </visual>
    <inertial>
      <mass value="1"/>
      <inertia ixx="1" ixy="0.0" ixz="0.0" iyy="1" iyz="0.0" izz="1"/>
    </inertial>
  </link>
  <joint name="cylinder_R_joint" type="revolute">
    <origin rpy="1.57079632675 0 0" xyz="-1.9549 -0.7994 1.3634"/>
    <parent link="upper_frame_link"/>
    <child link="cylinder_R_link"/>
    <axis xyz="0 0 1"/>
    <limit effort="100000" lower="-3.14" upper="3.14" velocity="100"/>
  </joint>
  <link name="rod_L_link">
    <visual>
      <geometry>
        <mesh filename="package://ic120_model/mesh/rod_L.stl"/>
      </geometry>
      <origin rpy="0 1.57079632675 1.57079632675" xyz="3.8283 -1.3754 2.3016"/>
      <material name="Gray">
        <color rgba="0.7 0.7 0.7 1.0"/>
      </material>
    </visual>
    <inertial>
      <mass value="1"/>
      <inertia ixx="1" ixy="0.0" ixz="0.0" iyy="1" iyz="0.0" izz="1"/>
    </inertial>
  </link>
  <!--
  cont -2.3068 0.0034 1.5619
  door -2.3766 0.0034 2.3817  -> -0.0698 0.8197 0.0
  rodL -0.7283 0.8016 1.3754  -> 1.5785 -0.1865 -0.7982  -> cw.x - pw.x , cw.z - pw.z,  -(cw.y - pw.y)
  -->
  <joint name="rod_L_joint" type="revolute">
    <origin rpy="0 0 0" xyz="1.5785 -0.1865 -0.7982"/>
    <parent link="container_link"/>
    <child link="rod_L_link"/>
    <axis xyz="0 0 1"/>
    <limit effort="100000" lower="-3.14" upper="3.14" velocity="100"/>
  </joint>
  <link name="rod_R_link">
    <visual>
      <geometry>
        <mesh filename="package://ic120_model/mesh/rod_R.stl"/>
      </geometry>
      <origin rpy="0 1.57079632675 1.57079632675" xyz="3.8283 -1.3754 0.7006"/>
      <material name="Gray">
        <color rgba="0.7 0.7 0.7 1.0"/>
      </material>
    </visual>
    <inertial>
      <mass value="1"/>
      <inertia ixx="1" ixy="0.0" ixz="0.0" iyy="1" iyz="0.0" izz="1"/>
    </inertial>
  </link>
  <!--
  cont -2.3068 0.0034 1.5619
  rodR -0.7283 -0.7994 1.375  -> 1.5785 -0.1865 0.8028  -> cw.x - pw.x , cw.z - pw.z,  -(cw.y - pw.y)
  -->
  <joint name="rod_R_joint" type="revolute">
    <origin rpy="0 0 0" xyz="1.5785 -0.1865 0.8028"/>
    <parent link="container_link"/>
    <child link="rod_R_link"/>
    <axis xyz="0 0 1"/>
    <limit effort="100000" lower="-3.14" upper="3.14" velocity="100"/>
  </joint>
  <!--
  <link name="cabin_link">
    <visual>
      <geometry>
        <mesh filename="package://ic120_model/mesh/cabin.stl"/>
      </geometry>
      <origin rpy="0 0 1.57079632675" xyz="3.1 -1.5 0"/>
      <material name="Black">
        <color rgba="0 0 0 1.0"/>
      </material>
    </visual>
    <inertial>
      <mass value="1"/>
      <inertia ixx="1" ixy="0.0" ixz="0.0" iyy="1" iyz="0.0" izz="1"/>
    </inertial>
  </link>
  <joint name="cabin_joint" type="fixed">
    <origin rpy="0 0 0" xyz="0 0 0"/>
    <parent link="track_frame_link"/>
    <child link="cabin_link"/>
    <axis xyz="0 0 1"/>
  </joint>
  <link name="cabin_window_link">
    <visual>
      <geometry>
        <mesh filename="package://ic120_model/mesh/cabin_window.stl"/>
      </geometry>
      <origin rpy="0 0 1.57079632675" xyz="3.1 -1.5 0"/>
      <material name="Gray">
        <color rgba="0.7 0.7 0.7 0.2"/>
      </material>
    </visual>
    <inertial>
      <mass value="1"/>
      <inertia ixx="1" ixy="0.0" ixz="0.0" iyy="1" iyz="0.0" izz="1"/>
    </inertial>
  </link>
  <joint name="cabin_window_joint" type="fixed">
    <origin rpy="0 0 0" xyz="0 0 0"/>
    <parent link="track_frame_link"/>
    <child link="cabin_window_link"/>
    <axis xyz="0 0 1"/>
  </joint>
  -->
  
  <!-- Sprockets -->
  
  <link name="sprocket_L_link">
    <visual>
      <geometry>
        <mesh filename="package://ic120_model/mesh/sprocket.stl"/>
      </geometry>
      <origin rpy="0 0 0" xyz="0 0 0"/>
      <material name="Gray">
        <color rgba="0.7 0.7 0.7 1.0"/>
      </material>
    </visual>
    <inertial>
      <mass value="1"/>
      <inertia ixx="1" ixy="0.0" ixz="0.0" iyy="1" iyz="0.0" izz="1"/>
    </inertial>
  </link>
  <joint name="sprocket_L_joint" type="continuous">
    <origin rpy="0 0 0" xyz="1.9759 0.8208 0.7054"/>
    <parent link="track_frame_link"/>
    <child link="sprocket_L_link"/>
    <axis xyz="0 1 0"/>
  </joint>
  <link name="sprocket_R_link">
    <visual>
      <geometry>
        <mesh filename="package://ic120_model/mesh/sprocket.stl"/>
      </geometry>
      <origin rpy="0 0 3.14159265359" xyz="0 0 0"/>
      <material name="Gray">
        <color rgba="0.7 0.7 0.7 1.0"/>
      </material>
    </visual>
    <inertial>
      <mass value="1"/>
      <inertia ixx="1" ixy="0.0" ixz="0.0" iyy="1" iyz="0.0" izz="1"/>
    </inertial>
  </link>
  <joint name="sprocket_R_joint" type="continuous">
    <origin rpy="0 0 0" xyz="1.9759 -0.8606 0.7054"/>
    <parent link="track_frame_link"/>
    <child link="sprocket_R_link"/>
    <axis xyz="0 1 0"/>
  </joint>
  
  <!-- Idlers -->
  
  <link name="idler_L_link">
    <visual>
      <geometry>
        <mesh filename="package://ic120_model/mesh/idler.stl"/>
      </geometry>
      <origin rpy="0 0 0" xyz="0 0 0"/>
      <material name="Gray">
        <color rgba="0.7 0.7 0.7 1.0"/>
      </material>
    </visual>
    <inertial>
      <mass value="1"/>
      <inertia ixx="1" ixy="0.0" ixz="0.0" iyy="1" iyz="0.0" izz="1"/>
    </inertial>
  </link>
  <joint name="idler_L_joint" type="continuous">
    <origin rpy="0 0 0" xyz="-1.7352 0.8208 0.7175"/>
    <parent link="track_frame_link"/>
    <child link="idler_L_link"/>
    <axis xyz="0 1 0"/>
  </joint>
  <link name="idler_R_link">
    <visual>
      <geometry>
        <mesh filename="package://ic120_model/mesh/idler.stl"/>
      </geometry>
      <origin rpy="0 0 3.14159265359" xyz="0 0 0"/>
      <material name="Gray">
        <color rgba="0.7 0.7 0.7 1.0"/>
      </material>
    </visual>
    <inertial>
      <mass value="1"/>
      <inertia ixx="1" ixy="0.0" ixz="0.0" iyy="1" iyz="0.0" izz="1"/>
    </inertial>
  </link>
  <joint name="idler_R_joint" type="continuous">
    <origin rpy="0 0 0" xyz="-1.7352 -0.8606 0.7175"/>
    <parent link="track_frame_link"/>
    <child link="idler_R_link"/>
    <axis xyz="0 1 0"/>
  </joint>
  
  <!-- Carrier Rollers -->
  
  <link name="carrier_roller_L1_link">
    <visual>
      <geometry>
        <mesh filename="package://ic120_model/mesh/carrier_roller.stl"/>
      </geometry>
      <origin rpy="0 0 0" xyz="0 0.2849 0"/>
      <material name="Gray">
        <color rgba="0.7 0.7 0.7 1.0"/>
      </material>
    </visual>
    <inertial>
      <mass value="1"/>
      <inertia ixx="1" ixy="0.0" ixz="0.0" iyy="1" iyz="0.0" izz="1"/>
    </inertial>
  </link>
  <joint name="carrier_roller_L1_joint" type="continuous">
    <origin rpy="0 0 0" xyz="0.8101 0.8208 0.9976"/>
    <parent link="track_frame_link"/>
    <child link="carrier_roller_L1_link"/>
    <axis xyz="0 1 0"/>
  </joint>
  <link name="carrier_roller_L2_link">
    <visual>
      <geometry>
        <mesh filename="package://ic120_model/mesh/carrier_roller.stl"/>
      </geometry>
      <origin rpy="0 0 0" xyz="0 0.2849 0"/>
      <material name="Gray">
        <color rgba="0.7 0.7 0.7 1.0"/>
      </material>
    </visual>
    <inertial>
      <mass value="1"/>
      <inertia ixx="1" ixy="0.0" ixz="0.0" iyy="1" iyz="0.0" izz="1"/>
    </inertial>
  </link>
  <joint name="carrier_roller_L2_joint" type="continuous">
    <origin rpy="0 0 0" xyz="-0.4839 0.8208 0.9976"/>
    <parent link="track_frame_link"/>
    <child link="carrier_roller_L2_link"/>
    <axis xyz="0 1 0"/>
  </joint>
  <link name="carrier_roller_R1_link">
    <visual>
      <geometry>
        <mesh filename="package://ic120_model/mesh/carrier_roller.stl"/>
      </geometry>
      <origin rpy="0 0 3.14159265359" xyz="0 -0.2849 0"/>
      <material name="Gray">
        <color rgba="0.7 0.7 0.7 1.0"/>
      </material>
    </visual>
    <inertial>
      <mass value="1"/>
      <inertia ixx="1" ixy="0.0" ixz="0.0" iyy="1" iyz="0.0" izz="1"/>
    </inertial>
  </link>
  <joint name="carrier_roller_R1_joint" type="continuous">
    <origin rpy="0 0 0" xyz="0.8101 -0.8606 0.9976"/>
    <parent link="track_frame_link"/>
    <child link="carrier_roller_R1_link"/>
    <axis xyz="0 1 0"/>
  </joint>
  <link name="carrier_roller_R2_link">
    <visual>
      <geometry>
        <mesh filename="package://ic120_model/mesh/carrier_roller.stl"/>
      </geometry>
      <origin rpy="0 0 3.14159265359" xyz="0 -0.2849 0"/>
      <material name="Gray">
        <color rgba="0.7 0.7 0.7 1.0"/>
      </material>
    </visual>
    <inertial>
      <mass value="1"/>
      <inertia ixx="1" ixy="0.0" ixz="0.0" iyy="1" iyz="0.0" izz="1"/>
    </inertial>
  </link>
  <joint name="carrier_roller_R2_joint" type="continuous">
    <origin rpy="0 0 0" xyz="-0.4839 -0.8606 0.9976"/>
    <parent link="track_frame_link"/>
    <child link="carrier_roller_R2_link"/>
    <axis xyz="0 1 0"/>
  </joint>
  
  <!-- Track Rollers -->
  
  <link name="track_roller_L1_link">
    <visual>
      <geometry>
        <mesh filename="package://ic120_model/mesh/track_roller.stl"/>
      </geometry>
      <origin rpy="0 0 0" xyz="0 0.2562 0"/>
      <material name="Gray">
        <color rgba="0.7 0.7 0.7 1.0"/>
      </material>
    </visual>
    <inertial>
      <mass value="1"/>
      <inertia ixx="1" ixy="0.0" ixz="0.0" iyy="1" iyz="0.0" izz="1"/>
    </inertial>
  </link>
  <joint name="track_roller_L1_joint" type="continuous">
    <origin rpy="0 0 0" xyz="1.5129 0.8208 0.303"/>
    <parent link="track_frame_link"/>
    <child link="track_roller_L1_link"/>
    <axis xyz="0 1 0"/>
  </joint>
  <link name="track_roller_L2_link">
    <visual>
      <geometry>
        <mesh filename="package://ic120_model/mesh/track_roller.stl"/>
      </geometry>
      <origin rpy="0 0 0" xyz="0 0.2562 0"/>
      <material name="Gray">
        <color rgba="0.7 0.7 0.7 1.0"/>
      </material>
    </visual>
    <inertial>
      <mass value="1"/>
      <inertia ixx="1" ixy="0.0" ixz="0.0" iyy="1" iyz="0.0" izz="1"/>
    </inertial>
  </link>
  <joint name="track_roller_L2_joint" type="continuous">
    <origin rpy="0 0 0" xyz="1.1056 0.8208 0.303"/>
    <parent link="track_frame_link"/>
    <child link="track_roller_L2_link"/>
    <axis xyz="0 1 0"/>
  </joint>
  <link name="track_roller_L3_link">
    <visual>
      <geometry>
        <mesh filename="package://ic120_model/mesh/track_roller.stl"/>
      </geometry>
      <origin rpy="0 0 0" xyz="0 0.2562 0"/>
      <material name="Gray">
        <color rgba="0.7 0.7 0.7 1.0"/>
      </material>
    </visual>
    <inertial>
      <mass value="1"/>
      <inertia ixx="1" ixy="0.0" ixz="0.0" iyy="1" iyz="0.0" izz="1"/>
    </inertial>
  </link>
  <joint name="track_roller_L3_joint" type="continuous">
    <origin rpy="0 0 0" xyz="0.7478 0.8208 0.303"/>
    <parent link="track_frame_link"/>
    <child link="track_roller_L3_link"/>
    <axis xyz="0 1 0"/>
  </joint>
  <link name="track_roller_L4_link">
    <visual>
      <geometry>
        <mesh filename="package://ic120_model/mesh/track_roller.stl"/>
      </geometry>
      <origin rpy="0 0 0" xyz="0 0.2562 0"/>
      <material name="Gray">
        <color rgba="0.7 0.7 0.7 1.0"/>
      </material>
    </visual>
    <inertial>
      <mass value="1"/>
      <inertia ixx="1" ixy="0.0" ixz="0.0" iyy="1" iyz="0.0" izz="1"/>
    </inertial>
  </link>
  <joint name="track_roller_L4_joint" type="continuous">
    <origin rpy="0 0 0" xyz="0.3398 0.8208 0.303"/>
    <parent link="track_frame_link"/>
    <child link="track_roller_L4_link"/>
    <axis xyz="0 1 0"/>
  </joint>
  <link name="track_roller_L5_link">
    <visual>
      <geometry>
        <mesh filename="package://ic120_model/mesh/track_roller.stl"/>
      </geometry>
      <origin rpy="0 0 0" xyz="0 0.2562 0"/>
      <material name="Gray">
        <color rgba="0.7 0.7 0.7 1.0"/>
      </material>
    </visual>
    <inertial>
      <mass value="1"/>
      <inertia ixx="1" ixy="0.0" ixz="0.0" iyy="1" iyz="0.0" izz="1"/>
    </inertial>
  </link>
  <joint name="track_roller_L5_joint" type="continuous">
    <origin rpy="0 0 0" xyz="-0.0025 0.8208 0.303"/>
    <parent link="track_frame_link"/>
    <child link="track_roller_L5_link"/>
    <axis xyz="0 1 0"/>
  </joint>
  <link name="track_roller_L6_link">
    <visual>
      <geometry>
        <mesh filename="package://ic120_model/mesh/track_roller.stl"/>
      </geometry>
      <origin rpy="0 0 0" xyz="0 0.2562 0"/>
      <material name="Gray">
        <color rgba="0.7 0.7 0.7 1.0"/>
      </material>
    </visual>
    <inertial>
      <mass value="1"/>
      <inertia ixx="1" ixy="0.0" ixz="0.0" iyy="1" iyz="0.0" izz="1"/>
    </inertial>
  </link>
  <joint name="track_roller_L6_joint" type="continuous">
    <origin rpy="0 0 0" xyz="-0.4095 0.8208 0.303"/>
    <parent link="track_frame_link"/>
    <child link="track_roller_L6_link"/>
    <axis xyz="0 1 0"/>
  </joint>
  <link name="track_roller_L7_link">
    <visual>
      <geometry>
        <mesh filename="package://ic120_model/mesh/track_roller.stl"/>
      </geometry>
      <origin rpy="0 0 0" xyz="0 0.2562 0"/>
      <material name="Gray">
        <color rgba="0.7 0.7 0.7 1.0"/>
      </material>
    </visual>
    <inertial>
      <mass value="1"/>
      <inertia ixx="1" ixy="0.0" ixz="0.0" iyy="1" iyz="0.0" izz="1"/>
    </inertial>
  </link>
  <joint name="track_roller_L7_joint" type="continuous">
    <origin rpy="0 0 0" xyz="-0.7454 0.8208 0.303"/>
    <parent link="track_frame_link"/>
    <child link="track_roller_L7_link"/>
    <axis xyz="0 1 0"/>
  </joint>
  <link name="track_roller_L8_link">
    <visual>
      <geometry>
        <mesh filename="package://ic120_model/mesh/track_roller.stl"/>
      </geometry>
      <origin rpy="0 0 0" xyz="0 0.2562 0"/>
      <material name="Gray">
        <color rgba="0.7 0.7 0.7 1.0"/>
      </material>
    </visual>
    <inertial>
      <mass value="1"/>
      <inertia ixx="1" ixy="0.0" ixz="0.0" iyy="1" iyz="0.0" izz="1"/>
    </inertial>
  </link>
  <joint name="track_roller_L8_joint" type="continuous">
    <origin rpy="0 0 0" xyz="-1.1586 0.8208 0.303"/>
    <parent link="track_frame_link"/>
    <child link="track_roller_L8_link"/>
    <axis xyz="0 1 0"/>
  </joint>
  
  <link name="track_roller_R1_link">
    <visual>
      <geometry>
        <mesh filename="package://ic120_model/mesh/track_roller.stl"/>
      </geometry>
      <origin rpy="0 0 3.14159265359" xyz="0 -0.2562 0"/>
      <material name="Gray">
        <color rgba="0.7 0.7 0.7 1.0"/>
      </material>
    </visual>
    <inertial>
      <mass value="1"/>
      <inertia ixx="1" ixy="0.0" ixz="0.0" iyy="1" iyz="0.0" izz="1"/>
    </inertial>
  </link>
  <joint name="track_roller_R1_joint" type="continuous">
    <origin rpy="0 0 0" xyz="1.5129 -0.8606 0.303"/>
    <parent link="track_frame_link"/>
    <child link="track_roller_R1_link"/>
    <axis xyz="0 1 0"/>
  </joint>
  <link name="track_roller_R2_link">
    <visual>
      <geometry>
        <mesh filename="package://ic120_model/mesh/track_roller.stl"/>
      </geometry>
      <origin rpy="0 0 3.14159265359" xyz="0 -0.2562 0"/>
      <material name="Gray">
        <color rgba="0.7 0.7 0.7 1.0"/>
      </material>
    </visual>
    <inertial>
      <mass value="1"/>
      <inertia ixx="1" ixy="0.0" ixz="0.0" iyy="1" iyz="0.0" izz="1"/>
    </inertial>
  </link>
  <joint name="track_roller_R2_joint" type="continuous">
    <origin rpy="0 0 0" xyz="1.1056 -0.8606 0.303"/>
    <parent link="track_frame_link"/>
    <child link="track_roller_R2_link"/>
    <axis xyz="0 1 0"/>
  </joint>
  <link name="track_roller_R3_link">
    <visual>
      <geometry>
        <mesh filename="package://ic120_model/mesh/track_roller.stl"/>
      </geometry>
      <origin rpy="0 0 3.14159265359" xyz="0 -0.2562 0"/>
      <material name="Gray">
        <color rgba="0.7 0.7 0.7 1.0"/>
      </material>
    </visual>
    <inertial>
      <mass value="1"/>
      <inertia ixx="1" ixy="0.0" ixz="0.0" iyy="1" iyz="0.0" izz="1"/>
    </inertial>
  </link>
  <joint name="track_roller_R3_joint" type="continuous">
    <origin rpy="0 0 0" xyz="0.7478 -0.8606 0.303"/>
    <parent link="track_frame_link"/>
    <child link="track_roller_R3_link"/>
    <axis xyz="0 1 0"/>
  </joint>
  <link name="track_roller_R4_link">
    <visual>
      <geometry>
        <mesh filename="package://ic120_model/mesh/track_roller.stl"/>
      </geometry>
      <origin rpy="0 0 3.14159265359" xyz="0 -0.2562 0"/>
      <material name="Gray">
        <color rgba="0.7 0.7 0.7 1.0"/>
      </material>
    </visual>
    <inertial>
      <mass value="1"/>
      <inertia ixx="1" ixy="0.0" ixz="0.0" iyy="1" iyz="0.0" izz="1"/>
    </inertial>
  </link>
  <joint name="track_roller_R4_joint" type="continuous">
    <origin rpy="0 0 0" xyz="0.3398 -0.8606 0.303"/>
    <parent link="track_frame_link"/>
    <child link="track_roller_R4_link"/>
    <axis xyz="0 1 0"/>
  </joint>
  <link name="track_roller_R5_link">
    <visual>
      <geometry>
        <mesh filename="package://ic120_model/mesh/track_roller.stl"/>
      </geometry>
      <origin rpy="0 0 3.14159265359" xyz="0 -0.2562 0"/>
      <material name="Gray">
        <color rgba="0.7 0.7 0.7 1.0"/>
      </material>
    </visual>
    <inertial>
      <mass value="1"/>
      <inertia ixx="1" ixy="0.0" ixz="0.0" iyy="1" iyz="0.0" izz="1"/>
    </inertial>
  </link>
  <joint name="track_roller_R5_joint" type="continuous">
    <origin rpy="0 0 0" xyz="-0.0025 -0.8606 0.303"/>
    <parent link="track_frame_link"/>
    <child link="track_roller_R5_link"/>
    <axis xyz="0 1 0"/>
  </joint>
  <link name="track_roller_R6_link">
    <visual>
      <geometry>
        <mesh filename="package://ic120_model/mesh/track_roller.stl"/>
      </geometry>
      <origin rpy="0 0 3.14159265359" xyz="0 -0.2562 0"/>
      <material name="Gray">
        <color rgba="0.7 0.7 0.7 1.0"/>
      </material>
    </visual>
    <inertial>
      <mass value="1"/>
      <inertia ixx="1" ixy="0.0" ixz="0.0" iyy="1" iyz="0.0" izz="1"/>
    </inertial>
  </link>
  <joint name="track_roller_R6_joint" type="continuous">
    <origin rpy="0 0 0" xyz="-0.4095 -0.8606 0.303"/>
    <parent link="track_frame_link"/>
    <child link="track_roller_R6_link"/>
    <axis xyz="0 1 0"/>
  </joint>
  <link name="track_roller_R7_link">
    <visual>
      <geometry>
        <mesh filename="package://ic120_model/mesh/track_roller.stl"/>
      </geometry>
      <origin rpy="0 0 3.14159265359" xyz="0 -0.2562 0"/>
      <material name="Gray">
        <color rgba="0.7 0.7 0.7 1.0"/>
      </material>
    </visual>
    <inertial>
      <mass value="1"/>
      <inertia ixx="1" ixy="0.0" ixz="0.0" iyy="1" iyz="0.0" izz="1"/>
    </inertial>
  </link>
  <joint name="track_roller_R7_joint" type="continuous">
    <origin rpy="0 0 0" xyz="-0.7454 -0.8606 0.303"/>
    <parent link="track_frame_link"/>
    <child link="track_roller_R7_link"/>
    <axis xyz="0 1 0"/>
  </joint>
  <link name="track_roller_R8_link">
    <visual>
      <geometry>
        <mesh filename="package://ic120_model/mesh/track_roller.stl"/>
      </geometry>
      <origin rpy="0 0 3.14159265359" xyz="0 -0.2562 0"/>
      <material name="Gray">
        <color rgba="0.7 0.7 0.7 1.0"/>
      </material>
    </visual>
    <inertial>
      <mass value="1"/>
      <inertia ixx="1" ixy="0.0" ixz="0.0" iyy="1" iyz="0.0" izz="1"/>
    </inertial>
  </link>
  <joint name="track_roller_R8_joint" type="continuous">
    <origin rpy="0 0 0" xyz="-1.1586 -0.8606 0.303"/>
    <parent link="track_frame_link"/>
    <child link="track_roller_R8_link"/>
    <axis xyz="0 1 0"/>
  </joint>
  
  <!--
  <link name="vessel_pin_link">
    <visual>
      <geometry>
        <box size="0.001 0.001 0.001"/>
      </geometry>
      <origin rpy="0 0 0" xyz="0 0 0"/>
      <material name="Gray">
        <color rgba="0.7 0.7 0.7 0.2"/>
      </material>
    </visual>
    <inertial>
      <origin xyz="0 0 0"/>
      <mass value="1.0e-03"/>
      <inertia ixx="1.0e-03" ixy="0.0" ixz="0.0" iyy="1.0e-03" iyz="0.0" izz="1.0e-03"/>
    </inertial>
  </link>
  <joint name="vessel_pin_joint" type="revolute">
    <origin rpy="0 0 0" xyz="-2 0 1.5"/>
    <parent link="base_link"/>
    <child link="vessel_pin_link"/>
    <axis xyz="0 1 0"/>
    <limit effort="1" lower="-3.14" upper="0" velocity="0.5"/>
  </joint>
  <link name="vessel_middle_link"/>
  <joint name="vessel_middle_joint" type="fixed">
    <origin rpy="0 0 0" xyz="1 0 1"/>
    <parent link="vessel_pin_link"/>
    <child link="vessel_middle_link"/>
  </joint>
  -->
</robot>
