<?xml version="1.0" ?>
<!-- =================================================================================== -->
<!-- |    This document was autogenerated by xacro from zx200.xacro                    | -->
<!-- |    EDITING THIS FILE BY HAND IS NOT RECOMMENDED                                 | -->
<!-- =================================================================================== -->
<robot name="zx200">
  <!-- Import all Gazebo-customization elements, including Gazebo colors -->
  <!-- <xacro:include filename="$(find zx200_description)/urdf/zx200.gazebo" /> -->
  <!-- Import Rviz colors -->
  <!-- <xacro:include filename="$(find zx200_description)/urdf/materials.xacro" /> -->
  <!-- Used for fixing robot to Gazebo 'base_link' -->
  <link name="link1"/>
  <joint name="fixed" type="fixed">
    <parent link="link1"/>
    <child link="link2"/>
  </joint>
  <!-- Base Link -->
  <link name="link2">
    <visual>
      <geometry>
        <mesh filename="package://meshes/zx200-crawler.dae"/>
      </geometry>
    </visual>
    <collision>
      <geometry>
        <mesh filename="package://meshes/zx200-crawler.dae"/>
      </geometry>
    </collision>
    <inertial>
      <origin rpy="0 0 0" xyz="0 0 0"/>
      <mass value="0.03"/>
      <inertia ixx="1.0" ixy="0.0" ixz="0.0" iyy="1.0" iyz="0.0" izz="1.0"/>
    </inertial>
  </link>
  <!-- body axis -->
  <joint name="joint1" type="continuous">
    <origin xyz="0.10787 -0.034301 1.1206"/>
    <axis xyz="0 0 1"/>
    <parent link="link2"/>
    <child link="link3"/>
  </joint>
  <link name="link3">
    <visual>
      <origin xyz="0 0 0"/>
      <geometry>
        <mesh filename="package://meshes/zx200-body.dae"/>
      </geometry>
    </visual>
    <collision>
      <origin xyz="0 0 0"/>
      <geometry>
        <mesh filename="package://meshes/zx200-body.dae"/>
      </geometry>
    </collision>
    <inertial>
      <origin rpy="0 0 0" xyz="0 0 0"/>
      <mass value="0.03"/>
      <inertia ixx="1.0" ixy="0.0" ixz="0.0" iyy="1.0" iyz="0.0" izz="1.0"/>
    </inertial>
  </link>
  <!-- boom axis -->
  <joint name="joint2" type="revolute">
    <origin xyz="0.22767 -0.040187 0.83669"/>
    <axis xyz="0 1 0"/>
    <parent link="link3"/>
    <child link="link4"/>
    <limit effort="500" lower="-0.3490658503988659" upper="0.9599310885968813" velocity="6.159937255"/>
  </joint>
  <joint name="joint5" type="continuous">
    <origin xyz="0.68912 -0.033576 0.23418"/>
    <axis xyz="0 1 0"/>
    <parent link="link3"/>
    <child link="link7"/>
    <mimic joint="joint2" multiplier="0.8785714285714286"/>
  </joint>
  <gazebo>
    <plugin filename="libroboticsgroup_upatras_gazebo_mimic_joint_plugin.so" name="joint5_mimic_joint_plugin">
      <joint>joint2</joint>
      <mimicJoint>joint5</mimicJoint>
      <multiplier>0.8571428571428571</multiplier>
      <offset>0</offset>
      <robotNamespace>/zx200</robotNamespace>
    </plugin>
  </gazebo>
  <joint name="joint6" type="prismatic">
    <origin xyz="0 0 0"/>
    <axis xyz="-0.2817 0 -0.74728"/>
    <parent link="link7"/>
    <child link="link8"/>
    <limit effort="500" lower="-2" upper="2" velocity="6.159937255"/>
    <mimic joint="joint2" multiplier="0.6557377049180328"/>
  </joint>
  <gazebo>
    <plugin filename="libroboticsgroup_upatras_gazebo_mimic_joint_plugin.so" name="joint6_mimic_joint_plugin">
      <joint>joint2</joint>
      <mimicJoint>joint6</mimicJoint>
      <multiplier>-0.319672131147541</multiplier>
      <offset>0</offset>
      <robotNamespace>/zx200</robotNamespace>
    </plugin>
  </gazebo>
  <joint name="joint7" type="fixed">
    <origin xyz="2.2875 0.017187 2.785"/>
    <axis xyz="0 1 0"/>
    <parent link="link4"/>
    <child link="link9"/>
  </joint>
  <joint name="joint8" type="prismatic">
    <origin xyz="0 0 0"/>
    <axis xyz="0.48707 0 0.17284"/>
    <parent link="link9"/>
    <child link="link10"/>
    <limit effort="500" lower="-2" upper="2" velocity="6.159937255"/>
    <mimic joint="joint3" multiplier="0.5156620156177409"/>
  </joint>
  <gazebo>
    <plugin filename="libroboticsgroup_upatras_gazebo_mimic_joint_plugin.so" name="joint8_mimic_joint_plugin">
      <joint>joint3</joint>
      <mimicJoint>joint8</mimicJoint>
      <multiplier>0.4583662361046586</multiplier>
      <offset>0</offset>
      <robotNamespace>/zx200</robotNamespace>
    </plugin>
  </gazebo>
  <joint name="joint9" type="fixed">
    <origin xyz="-0.24687 -0.007397 0.73594"/>
    <axis xyz="0 1 0"/>
    <parent link="link5"/>
    <child link="link11"/>
  </joint>
  <joint name="joint10" type="prismatic">
    <origin xyz="0 0 0"/>
    <axis xyz="0.14917 0 0.16252"/>
    <parent link="link11"/>
    <child link="link12"/>
    <limit effort="500" lower="-2" upper="2" velocity="6.159937255"/>
    <mimic joint="joint4" multiplier="0.3225806451612903"/>
  </joint>
  <gazebo>
    <plugin filename="libroboticsgroup_upatras_gazebo_mimic_joint_plugin.so" name="joint10_mimic_joint_plugin">
      <joint>joint4</joint>
      <mimicJoint>joint10</mimicJoint>
      <multiplier>0.3225806451612903</multiplier>
      <offset>0</offset>
      <robotNamespace>/zx200</robotNamespace>
    </plugin>
  </gazebo>
  <joint name="joint11" type="continuous">
    <origin xyz="1.5754 -0.01272 1.8799"/>
    <axis xyz="0 1 0"/>
    <parent link="link5"/>
    <child link="link13"/>
    <mimic joint="joint4" multiplier="0.75"/>
  </joint>
  <gazebo>
    <plugin filename="libroboticsgroup_upatras_gazebo_mimic_joint_plugin.so" name="joint11_mimic_joint_plugin">
      <joint>joint4</joint>
      <mimicJoint>joint11</mimicJoint>
      <multiplier>0.75</multiplier>
      <offset>0</offset>
      <robotNamespace>/zx200</robotNamespace>
    </plugin>
  </gazebo>
  <joint name="joint12" type="continuous">
    <origin xyz="-0.32404 -0.008096 0.33854"/>
    <axis xyz="0 1 0"/>
    <parent link="link6"/>
    <child link="link14"/>
    <mimic joint="joint4" multiplier="-1.3125"/>
  </joint>
  <gazebo>
    <plugin filename="libroboticsgroup_upatras_gazebo_mimic_joint_plugin.so" name="joint12_mimic_joint_plugin">
      <joint>joint4</joint>
      <mimicJoint>joint12</mimicJoint>
      <multiplier>-0.575</multiplier>
      <offset>0</offset>
      <robotNamespace>/zx200</robotNamespace>
    </plugin>
  </gazebo>
  <link name="link4">
    <visual>
      <origin xyz="0 0 0"/>
      <geometry>
        <mesh filename="package://meshes/zx200-boom.dae"/>
      </geometry>
    </visual>
    <collision>
      <origin xyz="0 0 0"/>
      <geometry>
        <mesh filename="package://meshes/zx200-boom.dae"/>
      </geometry>
    </collision>
    <inertial>
      <origin rpy="0 0 0" xyz="0 0 0"/>
      <mass value="0.03"/>
      <inertia ixx="1.0" ixy="0.0" ixz="0.0" iyy="1.0" iyz="0.0" izz="1.0"/>
    </inertial>
  </link>
  <joint name="joint3" type="revolute">
    <origin xyz="4.7878 0.010957 2.9959"/>
    <axis xyz="0 1 0"/>
    <parent link="link4"/>
    <child link="link5"/>
    <limit effort="500" lower="0.7853981633974483" upper="2.530727415391778" velocity="6.159937255"/>
  </joint>
  <link name="link5">
    <visual>
      <origin xyz="0 0 0"/>
      <geometry>
        <mesh filename="package://meshes/zx200-arm.dae"/>
      </geometry>
    </visual>
    <collision>
      <origin xyz="0 0 0"/>
      <geometry>
        <mesh filename="package://meshes/zx200-arm.dae"/>
      </geometry>
    </collision>
    <inertial>
      <origin rpy="0 0 0" xyz="0 0 0"/>
      <mass value="0.03"/>
      <inertia ixx="1.0" ixy="0.0" ixz="0.0" iyy="1.0" iyz="0.0" izz="1.0"/>
    </inertial>
  </link>
  <!-- bucket axis -->
  <joint name="joint4" type="revolute">
    <origin xyz="1.8954 -0.023546 2.1809"/>
    <axis xyz="0 1 0"/>
    <parent link="link5"/>
    <child link="link6"/>
    <limit effort="500" lower="-1.2217304763960306" upper="1.3962634015954636" velocity="6.159937255"/>
  </joint>
  <link name="link6">
    <visual>
      <origin xyz="0 0 0"/>
      <geometry>
        <mesh filename="package://meshes/zx200-bucket.dae"/>
      </geometry>
    </visual>
    <collision>
      <origin xyz="0 0 0"/>
      <geometry>
        <mesh filename="package://meshes/zx200-bucket.dae"/>
      </geometry>
    </collision>
    <inertial>
      <origin rpy="0 0 0" xyz="0 0 0"/>
      <mass value="0.03"/>
      <inertia ixx="1.0" ixy="0.0" ixz="0.0" iyy="1.0" iyz="0.0" izz="1.0"/>
    </inertial>
  </link>
  <link name="link7">
    <visual>
      <origin xyz="0 0 0"/>
      <geometry>
        <mesh filename="package://meshes/zx200-boom-cyl1.dae"/>
      </geometry>
    </visual>
    <collision>
      <origin xyz="0 0 0"/>
      <geometry>
        <mesh filename="package://meshes/zx200-boom-cyl1.dae"/>
      </geometry>
    </collision>
    <inertial>
      <origin rpy="0 0 0" xyz="0 0 0"/>
      <mass value="0.03"/>
      <inertia ixx="1.0" ixy="0.0" ixz="0.0" iyy="1.0" iyz="0.0" izz="1.0"/>
    </inertial>
  </link>
  <link name="link8">
    <visual>
      <origin xyz="0 0 0"/>
      <geometry>
        <mesh filename="package://meshes/zx200-boom-cyl2.dae"/>
      </geometry>
    </visual>
    <collision>
      <origin xyz="0 0 0"/>
      <geometry>
        <mesh filename="package://meshes/zx200-boom-cyl2.dae"/>
      </geometry>
    </collision>
    <inertial>
      <origin rpy="0 0 0" xyz="0 0 0"/>
      <mass value="0.03"/>
      <inertia ixx="1.0" ixy="0.0" ixz="0.0" iyy="1.0" iyz="0.0" izz="1.0"/>
    </inertial>
  </link>
  <link name="link9">
    <visual>
      <origin xyz="0 0 0"/>
      <geometry>
        <mesh filename="package://meshes/zx200-arm-cyl1.dae"/>
      </geometry>
    </visual>
    <collision>
      <origin xyz="0 0 0"/>
      <geometry>
        <mesh filename="package://meshes/zx200-arm-cyl1.dae"/>
      </geometry>
    </collision>
    <inertial>
      <origin rpy="0 0 0" xyz="0 0 0"/>
      <mass value="0.03"/>
      <inertia ixx="1.0" ixy="0.0" ixz="0.0" iyy="1.0" iyz="0.0" izz="1.0"/>
    </inertial>
  </link>
  <link name="link10">
    <visual>
      <origin xyz="0 0 0"/>
      <geometry>
        <mesh filename="package://meshes/zx200-arm-cyl2.dae"/>
      </geometry>
    </visual>
    <collision>
      <origin xyz="0 0 0"/>
      <geometry>
        <mesh filename="package://meshes/zx200-arm-cyl2.dae"/>
      </geometry>
    </collision>
    <inertial>
      <origin rpy="0 0 0" xyz="0 0 0"/>
      <mass value="0.03"/>
      <inertia ixx="1.0" ixy="0.0" ixz="0.0" iyy="1.0" iyz="0.0" izz="1.0"/>
    </inertial>
  </link>
  <link name="link11">
    <visual>
      <origin xyz="0 0 0"/>
      <geometry>
        <mesh filename="package://meshes/zx200-bucket-cyl1.dae"/>
      </geometry>
    </visual>
    <collision>
      <origin xyz="0 0 0"/>
      <geometry>
        <mesh filename="package://meshes/zx200-bucket-cyl1.dae"/>
      </geometry>
    </collision>
    <inertial>
      <origin rpy="0 0 0" xyz="0 0 0"/>
      <mass value="0.03"/>
      <inertia ixx="1.0" ixy="0.0" ixz="0.0" iyy="1.0" iyz="0.0" izz="1.0"/>
    </inertial>
  </link>
  <link name="link12">
    <visual>
      <origin xyz="0 0 0"/>
      <geometry>
        <mesh filename="package://meshes/zx200-bucket-cyl2.dae"/>
      </geometry>
    </visual>
    <collision>
      <origin xyz="0 0 0"/>
      <geometry>
        <mesh filename="package://meshes/zx200-bucket-cyl2.dae"/>
      </geometry>
    </collision>
    <inertial>
      <origin rpy="0 0 0" xyz="0 0 0"/>
      <mass value="0.03"/>
      <inertia ixx="1.0" ixy="0.0" ixz="0.0" iyy="1.0" iyz="0.0" izz="1.0"/>
    </inertial>
  </link>
  <link name="link13">
    <visual>
      <origin xyz="0 0 0"/>
      <geometry>
        <mesh filename="package://meshes/zx200-part1.dae"/>
      </geometry>
    </visual>
    <collision>
      <origin xyz="0 0 0"/>
      <geometry>
        <mesh filename="package://meshes/zx200-part1.dae"/>
      </geometry>
    </collision>
    <inertial>
      <origin rpy="0 0 0" xyz="0 0 0"/>
      <mass value="0.03"/>
      <inertia ixx="1.0" ixy="0.0" ixz="0.0" iyy="1.0" iyz="0.0" izz="1.0"/>
    </inertial>
  </link>
  <link name="link14">
    <visual>
      <origin xyz="0 0 0"/>
      <geometry>
        <mesh filename="package://meshes/zx200-part2.dae"/>
      </geometry>
    </visual>
    <collision>
      <origin xyz="0 0 0"/>
      <geometry>
        <mesh filename="package://meshes/zx200-part2.dae"/>
      </geometry>
    </collision>
    <inertial>
      <origin rpy="0 0 0" xyz="0 0 0"/>
      <mass value="0.03"/>
      <inertia ixx="1.0" ixy="0.0" ixz="0.0" iyy="1.0" iyz="0.0" izz="1.0"/>
    </inertial>
  </link>
  <transmission name="tran1">
    <type>transmission_interface/SimpleTransmission</type>
    <joint name="joint1">
      <hardwareInterface>hardware_interface/EffortJointInterface</hardwareInterface>
    </joint>
    <actuator name="motor1">
      <hardwareInterface>hardware_interface/EffortJointInterface</hardwareInterface>
      <mechanicalReduction>1</mechanicalReduction>
    </actuator>
  </transmission>
  <transmission name="tran2">
    <type>transmission_interface/SimpleTransmission</type>
    <joint name="joint2">
      <hardwareInterface>hardware_interface/EffortJointInterface</hardwareInterface>
    </joint>
    <actuator name="motor2">
      <hardwareInterface>hardware_interface/EffortJointInterface</hardwareInterface>
      <mechanicalReduction>1</mechanicalReduction>
    </actuator>
  </transmission>
  <transmission name="tran3">
    <type>transmission_interface/SimpleTransmission</type>
    <joint name="joint3">
      <hardwareInterface>hardware_interface/EffortJointInterface</hardwareInterface>
    </joint>
    <actuator name="motor3">
      <hardwareInterface>hardware_interface/EffortJointInterface</hardwareInterface>
      <mechanicalReduction>1</mechanicalReduction>
    </actuator>
  </transmission>
  <transmission name="tran4">
    <type>transmission_interface/SimpleTransmission</type>
    <joint name="joint4">
      <hardwareInterface>hardware_interface/EffortJointInterface</hardwareInterface>
    </joint>
    <actuator name="motor4">
      <hardwareInterface>hardware_interface/EffortJointInterface</hardwareInterface>
      <mechanicalReduction>1</mechanicalReduction>
    </actuator>
  </transmission>
</robot>
